 * Debug mode: off
Traceback (most recent call last):
  File "/home/runner/workspace/web_main.py", line 47, in <module>
    run_bssci_service()
  File "/home/runner/workspace/web_main.py", line 27, in run_bssci_service
    asyncio.run(bssci_main())
  File "/nix/store/h097imm3w6dpx10qynrd2sz9fks2wbq8-python3-3.12.11/lib/python3.12/asyncio/runners.py", line 195, in run
    return runner.run(main)
           ^^^^^^^^^^^^^^^^
  File "/nix/store/h097imm3w6dpx10qynrd2sz9fks2wbq8-python3-3.12.11/lib/python3.12/asyncio/runners.py", line 118, in run
    return self._loop.run_until_complete(task)
           ^^^^^^^^^^^^^^^^^^^^^^^^^^^^^^^^^^^
  File "/nix/store/h097imm3w6dpx10qynrd2sz9fks2wbq8-python3-3.12.11/lib/python3.12/asyncio/base_events.py", line 691, in run_until_complete
    return future.result()
           ^^^^^^^^^^^^^^^
  File "/home/runner/workspace/main.py", line 36, in main
    await asyncio.gather(tls_task, mqtt_task)
  File "/home/runner/workspace/TLSServer.py", line 72, in start_server
    server = await asyncio.start_server(
             ^^^^^^^^^^^^^^^^^^^^^^^^^^^
  File "/nix/store/h097imm3w6dpx10qynrd2sz9fks2wbq8-python3-3.12.11/lib/python3.12/asyncio/streams.py", line 84, in start_server
    return await loop.create_server(factory, host, port, **kwds)
           ^^^^^^^^^^^^^^^^^^^^^^^^^^^^^^^^^^^^^^^^^^^^^^^^^^^^^
  File "/nix/store/h097imm3w6dpx10qynrd2sz9fks2wbq8-python3-3.12.11/lib/python3.12/asyncio/base_events.py", line 1584, in create_server
    raise OSError(err.errno, msg) from None
OSError: [Errno 98] error while attempting to bind on address ('0.0.0.0', 16018): [errno 98] address already in use
Exception ignored in: <bound method BaseEventLoop.call_exception_handler of <_UnixSelectorEventLoop running=False closed=True debug=False>>
Traceback (most recent call last):
  File "/nix/store/h097imm3w6dpx10qynrd2sz9fks2wbq8-python3-3.12.11/lib/python3.12/asyncio/base_events.py", line 1866, in call_exception_handler
  File "/nix/store/h097imm3w6dpx10qynrd2sz9fks2wbq8-python3-3.12.11/lib/python3.12/logging/__init__.py", line 1568, in error
  File "/nix/store/h097imm3w6dpx10qynrd2sz9fks2wbq8-python3-3.12.11/lib/python3.12/logging/__init__.py", line 1684, in _log
  File "/nix/store/h097imm3w6dpx10qynrd2sz9fks2wbq8-python3-3.12.11/lib/python3.12/logging/__init__.py", line 1700, in handle
  File "/nix/store/h097imm3w6dpx10qynrd2sz9fks2wbq8-python3-3.12.11/lib/python3.12/logging/__init__.py", line 1762, in callHandlers
  File "/nix/store/h097imm3w6dpx10qynrd2sz9fks2wbq8-python3-3.12.11/lib/python3.12/logging/__init__.py", line 1028, in handle
  File "/home/runner/workspace/web_ui.py", line 33, in emit
ImportError: sys.meta_path is None, Python is likely shutting down
Exception ignored in: <function Client.__del__ at 0x7f298bc613a0>
Traceback (most recent call last):
  File "/home/runner/workspace/.pythonlibs/lib/python3.12/site-packages/paho/mqtt/client.py", line 880, in __del__
  File "/home/runner/workspace/.pythonlibs/lib/python3.12/site-packages/paho/mqtt/client.py", line 1139, in _reset_sockets
  File "/home/runner/workspace/.pythonlibs/lib/python3.12/site-packages/paho/mqtt/client.py", line 1132, in _sock_close
  File "/home/runner/workspace/.pythonlibs/lib/python3.12/site-packages/paho/mqtt/client.py", line 2869, in _call_socket_close
  File "/home/runner/workspace/.pythonlibs/lib/python3.12/site-packages/paho/mqtt/client.py", line 3259, in _easy_log
  File "/nix/store/h097imm3w6dpx10qynrd2sz9fks2wbq8-python3-3.12.11/lib/python3.12/logging/__init__.py", line 1609, in log
  File "/nix/store/h097imm3w6dpx10qynrd2sz9fks2wbq8-python3-3.12.11/lib/python3.12/logging/__init__.py", line 1684, in _log
  File "/nix/store/h097imm3w6dpx10qynrd2sz9fks2wbq8-python3-3.12.11/lib/python3.12/logging/__init__.py", line 1700, in handle
  File "/nix/store/h097imm3w6dpx10qynrd2sz9fks2wbq8-python3-3.12.11/lib/python3.12/logging/__init__.py", line 1762, in callHandlers
  File "/nix/store/h097imm3w6dpx10qynrd2sz9fks2wbq8-python3-3.12.11/lib/python3.12/logging/__init__.py", line 1028, in handle
  File "/home/runner/workspace/web_ui.py", line 33, in emit
 * Serving Flask app 'web_ui' None, Python is likely shutting down
 * Debug mode: off
Traceback (most recent call last):
  File "/home/runner/workspace/web_main.py", line 47, in <module>
    run_bssci_service()
  File "/home/runner/workspace/web_main.py", line 27, in run_bssci_service
    asyncio.run(bssci_main())
  File "/nix/store/h097imm3w6dpx10qynrd2sz9fks2wbq8-python3-3.12.11/lib/python3.12/asyncio/runners.py", line 195, in run
    return runner.run(main)
           ^^^^^^^^^^^^^^^^
  File "/nix/store/h097imm3w6dpx10qynrd2sz9fks2wbq8-python3-3.12.11/lib/python3.12/asyncio/runners.py", line 118, in run
    return self._loop.run_until_complete(task)
           ^^^^^^^^^^^^^^^^^^^^^^^^^^^^^^^^^^^
  File "/nix/store/h097imm3w6dpx10qynrd2sz9fks2wbq8-python3-3.12.11/lib/python3.12/asyncio/base_events.py", line 691, in run_until_complete
    return future.result()
           ^^^^^^^^^^^^^^^
  File "/home/runner/workspace/main.py", line 36, in main
    await asyncio.gather(tls_task, mqtt_task)
  File "/home/runner/workspace/TLSServer.py", line 72, in start_server
    server = await asyncio.start_server(
             ^^^^^^^^^^^^^^^^^^^^^^^^^^^
  File "/nix/store/h097imm3w6dpx10qynrd2sz9fks2wbq8-python3-3.12.11/lib/python3.12/asyncio/streams.py", line 84, in start_server
    return await loop.create_server(factory, host, port, **kwds)
           ^^^^^^^^^^^^^^^^^^^^^^^^^^^^^^^^^^^^^^^^^^^^^^^^^^^^^
  File "/nix/store/h097imm3w6dpx10qynrd2sz9fks2wbq8-python3-3.12.11/lib/python3.12/asyncio/base_events.py", line 1584, in create_server
    raise OSError(err.errno, msg) from None
OSError: [Errno 98] error while attempting to bind on address ('0.0.0.0', 16018): [errno 98] address already in use
Exception ignored in: <bound method BaseEventLoop.call_exception_handler of <_UnixSelectorEventLoop running=False closed=True debug=False>>
Traceback (most recent call last):
  File "/nix/store/h097imm3w6dpx10qynrd2sz9fks2wbq8-python3-3.12.11/lib/python3.12/asyncio/base_events.py", line 1866, in call_exception_handler
  File "/nix/store/h097imm3w6dpx10qynrd2sz9fks2wbq8-python3-3.12.11/lib/python3.12/logging/__init__.py", line 1568, in error
  File "/nix/store/h097imm3w6dpx10qynrd2sz9fks2wbq8-python3-3.12.11/lib/python3.12/logging/__init__.py", line 1684, in _log
  File "/nix/store/h097imm3w6dpx10qynrd2sz9fks2wbq8-python3-3.12.11/lib/python3.12/logging/__init__.py", line 1700, in handle
  File "/nix/store/h097imm3w6dpx10qynrd2sz9fks2wbq8-python3-3.12.11/lib/python3.12/logging/__init__.py", line 1762, in callHandlers
  File "/nix/store/h097imm3w6dpx10qynrd2sz9fks2wbq8-python3-3.12.11/lib/python3.12/logging/__init__.py", line 1028, in handle
  File "/home/runner/workspace/web_ui.py", line 33, in emit
ImportError: sys.meta_path is None, Python is likely shutting down
Exception ignored in: <function Client.__del__ at 0x7f298bc613a0>
Traceback (most recent call last):
  File "/home/runner/workspace/.pythonlibs/lib/python3.12/site-packages/paho/mqtt/client.py", line 880, in __del__
  File "/home/runner/workspace/.pythonlibs/lib/python3.12/site-packages/paho/mqtt/client.py", line 1139, in _reset_sockets
  File "/home/runner/workspace/.pythonlibs/lib/python3.12/site-packages/paho/mqtt/client.py", line 1132, in _sock_close
  File "/home/runner/workspace/.pythonlibs/lib/python3.12/site-packages/paho/mqtt/client.py", line 2869, in _call_socket_close
  File "/home/runner/workspace/.pythonlibs/lib/python3.12/site-packages/paho/mqtt/client.py", line 3259, in _easy_log
  File "/nix/store/h097imm3w6dpx10qynrd2sz9fks2wbq8-python3-3.12.11/lib/python3.12/logging/__init__.py", line 1609, in log
  File "/nix/store/h097imm3w6dpx10qynrd2sz9fks2wbq8-python3-3.12.11/lib/python3.12/logging/__init__.py", line 1684, in _log
  File "/nix/store/h097imm3w6dpx10qynrd2sz9fks2wbq8-python3-3.12.11/lib/python3.12/logging/__init__.py", line 1700, in handle
  File "/nix/store/h097imm3w6dpx10qynrd2sz9fks2wbq8-python3-3.12.11/lib/python3.12/logging/__init__.py", line 1762, in callHandlers
  File "/nix/store/h097imm3w6dpx10qynrd2sz9fks2wbq8-python3-3.12.11/lib/python3.12/logging/__init__.py", line 1028, in handle
  File "/home/runner/workspace/web_ui.py", line 33, in emit